(dp1
S'output'
p2
S"<type 'exceptions.AttributeError'> "
p3
sS'layer'
p4
S'/Users/rafihaque/Documents/cmps183/web2py/applications/hicappo/controllers/api.py'
p5
sS'code'
p6
S'<code object <module> at 0x10dd1a6b0, file "/Users/rafihaque/Documents/cmps183/web2py/applications/hicappo/controllers/api.py", line 3>'
p7
sS'snapshot'
p8
(dp9
sS'traceback'
p10
S'Traceback (most recent call last):\n  File "/Users/rafihaque/Documents/cmps183/web2py/gluon/restricted.py", line 219, in restricted\n    exec(ccode, environment)\n  File "/Users/rafihaque/Documents/cmps183/web2py/applications/hicappo/controllers/api.py", line 134, in <module>\n  File "/Users/rafihaque/Documents/cmps183/web2py/gluon/globals.py", line 419, in <lambda>\n    self._caller = lambda f: f()\n  File "/Users/rafihaque/Documents/cmps183/web2py/applications/hicappo/controllers/api.py", line 128, in find_temp_listings\n    for m in db(db.listing.id == r.listindid):\n  File "/Users/rafihaque/Documents/cmps183/web2py/gluon/packages/dal/pydal/objects.py", line 111, in __getattr__\n    raise AttributeError\nAttributeError\n'
p11
s.