(dp1
S'output'
p2
S"<class 'sqlite3.IntegrityError'> FOREIGN KEY constraint failed"
p3
sS'layer'
p4
S'/Users/rafihaque/Documents/cmps183/web2py/applications/hicappo/controllers/api.py'
p5
sS'code'
p6
S'<code object <module> at 0x1065b8db0, file "/Users/rafihaque/Documents/cmps183/web2py/applications/hicappo/controllers/api.py", line 3>'
p7
sS'snapshot'
p8
(dp9
sS'traceback'
p10
S'Traceback (most recent call last):\n  File "/Users/rafihaque/Documents/cmps183/web2py/gluon/restricted.py", line 219, in restricted\n    exec(ccode, environment)\n  File "/Users/rafihaque/Documents/cmps183/web2py/applications/hicappo/controllers/api.py", line 74, in <module>\n  File "/Users/rafihaque/Documents/cmps183/web2py/gluon/globals.py", line 419, in <lambda>\n    self._caller = lambda f: f()\n  File "/Users/rafihaque/Documents/cmps183/web2py/gluon/tools.py", line 3982, in f\n    return action(*a, **b)\n  File "/Users/rafihaque/Documents/cmps183/web2py/applications/hicappo/controllers/api.py", line 43, in addListing\n    groupid = request.vars.form_group\n  File "/Users/rafihaque/Documents/cmps183/web2py/gluon/packages/dal/pydal/objects.py", line 753, in insert\n    ret = self._db._adapter.insert(self, row.op_values())\n  File "/Users/rafihaque/Documents/cmps183/web2py/gluon/packages/dal/pydal/adapters/base.py", line 486, in insert\n    raise e\nIntegrityError: FOREIGN KEY constraint failed\n'
p11
s.